Workbook

Sheet Sheet1
A1: company_name | B1: pic_name | C1: designation | D1: Number already exists in Master DB? contact_number1 | E1: Number already exists in Master DB? contact_number2 | F1: Number already exists in Master DB? contact_number3 | G1: Number already exists in Master DB? contact_number4 | H1: Number already exists in Master DB? contact_number5 | I1: Number already exists in Master DB? contact_number6 | J1: Number already exists in Master DB? contact_number7 | K1: Number already exists in Master DB? contact_number8 | L1: concat_contact_numbers | M1: contact_number 1 | N1: contact_number 2 | O1: contact_number 3 | P1: contact_number 4 | Q1: contact_number 5 | R1: contact_number 6 | S1: contact_number 7 | T1: contact_number 8 | U1: email_address | V1: address
A2: TAMJAI SAMGOR MIXIAN | B2: Micky Gan | D2: =COUNTIF('Duplicates_with_Master DB'!$A:$A,Sheet1!M2)>0 -> FALSE | E2: =COUNTIF('Duplicates_with_Master DB'!$A:$A,Sheet1!N2)>0 -> FALSE | F2: =COUNTIF('Duplicates_with_Master DB'!$A:$A,Sheet1!O2)>0 -> FALSE | G2: =COUNTIF('Duplicates_with_Master DB'!$A:$A,Sheet1!P2)>0 -> FALSE | H2: =COUNTIF('Duplicates_with_Master DB'!$A:$A,Sheet1!Q2)>0 -> FALSE | I2: =COUNTIF('Duplicates_with_Master DB'!$A:$A,Sheet1!R2)>0 -> FALSE | J2: =COUNTIF('Duplicates_with_Master DB'!$A:$A,Sheet1!S2)>0 -> FALSE | K2: =COUNTIF('Duplicates_with_Master DB'!$A:$A,Sheet1!T2)>0 -> FALSE | L2: =M2 & IF(COUNTA(N2:T2), ", " & _xlfn.TEXTJOIN(", ", TRUE, N2:T2), "") -> 65131787 | M2: 65131787 | U2: micky.gan@tamjai-inti.com.sg
A3: fair trade commodities | B3: melissa ang | D3: =COUNTIF('Duplicates_with_Master DB'!$A:$A,Sheet1!M3)>0 -> FALSE | E3: =COUNTIF('Duplicates_with_Master DB'!$A:$A,Sheet1!N3)>0 -> FALSE | F3: =COUNTIF('Duplicates_with_Master DB'!$A:$A,Sheet1!O3)>0 -> FALSE | G3: =COUNTIF('Duplicates_with_Master DB'!$A:$A,Sheet1!P3)>0 -> FALSE | H3: =COUNTIF('Duplicates_with_Master DB'!$A:$A,Sheet1!Q3)>0 -> FALSE | I3: =COUNTIF('Duplicates_with_Master DB'!$A:$A,Sheet1!R3)>0 -> FALSE | J3: =COUNTIF('Duplicates_with_Master DB'!$A:$A,Sheet1!S3)>0 -> FALSE | K3: =COUNTIF('Duplicates_with_Master DB'!$A:$A,Sheet1!T3)>0 -> FALSE | L3: =M3 & IF(COUNTA(N3:T3), ", " & _xlfn.TEXTJOIN(", ", TRUE, N3:T3), "") | U3: pa10.md@fairtradeasean.com
A4: forintech | B4: ian li | D4: =COUNTIF('Duplicates_with_Master DB'!$A:$A,Sheet1!M4)>0 -> FALSE | E4: =COUNTIF('Duplicates_with_Master DB'!$A:$A,Sheet1!N4)>0 -> FALSE | F4: =COUNTIF('Duplicates_with_Master DB'!$A:$A,Sheet1!O4)>0 -> FALSE | G4: =COUNTIF('Duplicates_with_Master DB'!$A:$A,Sheet1!P4)>0 -> FALSE | H4: =COUNTIF('Duplicates_with_Master DB'!$A:$A,Sheet1!Q4)>0 -> FALSE | I4: =COUNTIF('Duplicates_with_Master DB'!$A:$A,Sheet1!R4)>0 -> FALSE | J4: =COUNTIF('Duplicates_with_Master DB'!$A:$A,Sheet1!S4)>0 -> FALSE | K4: =COUNTIF('Duplicates_with_Master DB'!$A:$A,Sheet1!T4)>0 -> FALSE | L4: =M4 & IF(COUNTA(N4:T4), ", " & _xlfn.TEXTJOIN(", ", TRUE, N4:T4), "") -> 81323868 | M4: 81323868 | U4: ian.li@forintechasia.com
A5: culinarte | B5: rahul gladwin massey | D5: =COUNTIF('Duplicates_with_Master DB'!$A:$A,Sheet1!M5)>0 -> FALSE | E5: =COUNTIF('Duplicates_with_Master DB'!$A:$A,Sheet1!N5)>0 -> FALSE | F5: =COUNTIF('Duplicates_with_Master DB'!$A:$A,Sheet1!O5)>0 -> FALSE | G5: =COUNTIF('Duplicates_with_Master DB'!$A:$A,Sheet1!P5)>0 -> FALSE | H5: =COUNTIF('Duplicates_with_Master DB'!$A:$A,Sheet1!Q5)>0 -> FALSE | I5: =COUNTIF('Duplicates_with_Master DB'!$A:$A,Sheet1!R5)>0 -> FALSE | J5: =COUNTIF('Duplicates_with_Master DB'!$A:$A,Sheet1!S5)>0 -> FALSE | K5: =COUNTIF('Duplicates_with_Master DB'!$A:$A,Sheet1!T5)>0 -> FALSE | L5: =M5 & IF(COUNTA(N5:T5), ", " & _xlfn.TEXTJOIN(", ", TRUE, N5:T5), "") | U5: rahul@culinarte.in
A6: oxford acuity | B6: potnanee darakamas | D6: =COUNTIF('Duplicates_with_Master DB'!$A:$A,Sheet1!M6)>0 -> FALSE | E6: =COUNTIF('Duplicates_with_Master DB'!$A:$A,Sheet1!N6)>0 -> FALSE | F6: =COUNTIF('Duplicates_with_Master DB'!$A:$A,Sheet1!O6)>0 -> FALSE | G6: =COUNTIF('Duplicates_with_Master DB'!$A:$A,Sheet1!P6)>0 -> FALSE | H6: =COUNTIF('Duplicates_with_Master DB'!$A:$A,Sheet1!Q6)>0 -> FALSE | I6: =COUNTIF('Duplicates_with_Master DB'!$A:$A,Sheet1!R6)>0 -> FALSE | J6: =COUNTIF('Duplicates_with_Master DB'!$A:$A,Sheet1!S6)>0 -> FALSE | K6: =COUNTIF('Duplicates_with_Master DB'!$A:$A,Sheet1!T6)>0 -> FALSE | L6: =M6 & IF(COUNTA(N6:T6), ", " & _xlfn.TEXTJOIN(", ", TRUE, N6:T6), "") | U6: potjanee@oxfordacuity.com
A7: The Denzy Collective | B7: Kelvin toh | D7: =COUNTIF('Duplicates_with_Master DB'!$A:$A,Sheet1!M7)>0 -> FALSE | E7: =COUNTIF('Duplicates_with_Master DB'!$A:$A,Sheet1!N7)>0 -> FALSE | F7: =COUNTIF('Duplicates_with_Master DB'!$A:$A,Sheet1!O7)>0 -> FALSE | G7: =COUNTIF('Duplicates_with_Master DB'!$A:$A,Sheet1!P7)>0 -> FALSE | H7: =COUNTIF('Duplicates_with_Master DB'!$A:$A,Sheet1!Q7)>0 -> FALSE | I7: =COUNTIF('Duplicates_with_Master DB'!$A:$A,Sheet1!R7)>0 -> FALSE | J7: =COUNTIF('Duplicates_with_Master DB'!$A:$A,Sheet1!S7)>0 -> FALSE | K7: =COUNTIF('Duplicates_with_Master DB'!$A:$A,Sheet1!T7)>0 -> FALSE | L7: =M7 & IF(COUNTA(N7:T7), ", " & _xlfn.TEXTJOIN(", ", TRUE, N7:T7), "") -> 93864782 | M7: 93864782 | U7: kel@denzy.com
A8: international foodgnostic | B8: Richard Tay | D8: =COUNTIF('Duplicates_with_Master DB'!$A:$A,Sheet1!M8)>0 -> FALSE | E8: =COUNTIF('Duplicates_with_Master DB'!$A:$A,Sheet1!N8)>0 -> FALSE | F8: =COUNTIF('Duplicates_with_Master DB'!$A:$A,Sheet1!O8)>0 -> FALSE | G8: =COUNTIF('Duplicates_with_Master DB'!$A:$A,Sheet1!P8)>0 -> FALSE | H8: =COUNTIF('Duplicates_with_Master DB'!$A:$A,Sheet1!Q8)>0 -> FALSE | I8: =COUNTIF('Duplicates_with_Master DB'!$A:$A,Sheet1!R8)>0 -> FALSE | J8: =COUNTIF('Duplicates_with_Master DB'!$A:$A,Sheet1!S8)>0 -> FALSE | K8: =COUNTIF('Duplicates_with_Master DB'!$A:$A,Sheet1!T8)>0 -> FALSE | L8: =M8 & IF(COUNTA(N8:T8), ", " & _xlfn.TEXTJOIN(", ", TRUE, N8:T8), "") -> 96874191 | M8: 96874191 | U8: richard_tay@foodgnostic.com
A9: Hosanna freight and logistics pte ltd | B9: Yanti | D9: =COUNTIF('Duplicates_with_Master DB'!$A:$A,Sheet1!M9)>0 -> FALSE | E9: =COUNTIF('Duplicates_with_Master DB'!$A:$A,Sheet1!N9)>0 -> FALSE | F9: =COUNTIF('Duplicates_with_Master DB'!$A:$A,Sheet1!O9)>0 -> FALSE | G9: =COUNTIF('Duplicates_with_Master DB'!$A:$A,Sheet1!P9)>0 -> FALSE | H9: =COUNTIF('Duplicates_with_Master DB'!$A:$A,Sheet1!Q9)>0 -> FALSE | I9: =COUNTIF('Duplicates_with_Master DB'!$A:$A,Sheet1!R9)>0 -> FALSE | J9: =COUNTIF('Duplicates_with_Master DB'!$A:$A,Sheet1!S9)>0 -> FALSE | K9: =COUNTIF('Duplicates_with_Master DB'!$A:$A,Sheet1!T9)>0 -> FALSE | L9: =M9 & IF(COUNTA(N9:T9), ", " & _xlfn.TEXTJOIN(", ", TRUE, N9:T9), "") -> 96778810 | M9: 96778810 | U9: yanti.tang@hosannafreight.com.sg
A10: Yamato izakaya | B10: Ryan | D10: =COUNTIF('Duplicates_with_Master DB'!$A:$A,Sheet1!M10)>0 -> FALSE | E10: =COUNTIF('Duplicates_with_Master DB'!$A:$A,Sheet1!N10)>0 -> FALSE | F10: =COUNTIF('Duplicates_with_Master DB'!$A:$A,Sheet1!O10)>0 -> FALSE | G10: =COUNTIF('Duplicates_with_Master DB'!$A:$A,Sheet1!P10)>0 -> FALSE | H10: =COUNTIF('Duplicates_with_Master DB'!$A:$A,Sheet1!Q10)>0 -> FALSE | I10: =COUNTIF('Duplicates_with_Master DB'!$A:$A,Sheet1!R10)>0 -> FALSE | J10: =COUNTIF('Duplicates_with_Master DB'!$A:$A,Sheet1!S10)>0 -> FALSE | K10: =COUNTIF('Duplicates_with_Master DB'!$A:$A,Sheet1!T10)>0 -> FALSE | L10: =M10 & IF(COUNTA(N10:T10), ", " & _xlfn.TEXTJOIN(", ", TRUE, N10:T10), "") -> 97888918 | M10: 97888918 | U10: nil123@gmail.com
A11: Asiaworld Developments | B11: Genny chua | D11: =COUNTIF('Duplicates_with_Master DB'!$A:$A,Sheet1!M11)>0 -> FALSE | E11: =COUNTIF('Duplicates_with_Master DB'!$A:$A,Sheet1!N11)>0 -> FALSE | F11: =COUNTIF('Duplicates_with_Master DB'!$A:$A,Sheet1!O11)>0 -> FALSE | G11: =COUNTIF('Duplicates_with_Master DB'!$A:$A,Sheet1!P11)>0 -> FALSE | H11: =COUNTIF('Duplicates_with_Master DB'!$A:$A,Sheet1!Q11)>0 -> FALSE | I11: =COUNTIF('Duplicates_with_Master DB'!$A:$A,Sheet1!R11)>0 -> FALSE | J11: =COUNTIF('Duplicates_with_Master DB'!$A:$A,Sheet1!S11)>0 -> FALSE | K11: =COUNTIF('Duplicates_with_Master DB'!$A:$A,Sheet1!T11)>0 -> FALSE | L11: =M11 & IF(COUNTA(N11:T11), ", " & _xlfn.TEXTJOIN(", ", TRUE, N11:T11), "") -> 97325246 | M11: 97325246 | U11: asiaworld1000@yahoo.com
A12: Every Intl | B12: Andy Kuo | D12: =COUNTIF('Duplicates_with_Master DB'!$A:$A,Sheet1!M12)>0 -> FALSE | E12: =COUNTIF('Duplicates_with_Master DB'!$A:$A,Sheet1!N12)>0 -> FALSE | F12: =COUNTIF('Duplicates_with_Master DB'!$A:$A,Sheet1!O12)>0 -> FALSE | G12: =COUNTIF('Duplicates_with_Master DB'!$A:$A,Sheet1!P12)>0 -> FALSE | H12: =COUNTIF('Duplicates_with_Master DB'!$A:$A,Sheet1!Q12)>0 -> FALSE | I12: =COUNTIF('Duplicates_with_Master DB'!$A:$A,Sheet1!R12)>0 -> FALSE | J12: =COUNTIF('Duplicates_with_Master DB'!$A:$A,Sheet1!S12)>0 -> FALSE | K12: =COUNTIF('Duplicates_with_Master DB'!$A:$A,Sheet1!T12)>0 -> FALSE | L12: =M12 & IF(COUNTA(N12:T12), ", " & _xlfn.TEXTJOIN(", ", TRUE, N12:T12), "") -> 93821449 | M12: 93821449 | U12: andykuo76@gmail.com
A13: Läderach Chocolatier | B13: Alexander | D13: =COUNTIF('Duplicates_with_Master DB'!$A:$A,Sheet1!M13)>0 -> FALSE | E13: =COUNTIF('Duplicates_with_Master DB'!$A:$A,Sheet1!N13)>0 -> FALSE | F13: =COUNTIF('Duplicates_with_Master DB'!$A:$A,Sheet1!O13)>0 -> FALSE | G13: =COUNTIF('Duplicates_with_Master DB'!$A:$A,Sheet1!P13)>0 -> FALSE | H13: =COUNTIF('Duplicates_with_Master DB'!$A:$A,Sheet1!Q13)>0 -> FALSE | I13: =COUNTIF('Duplicates_with_Master DB'!$A:$A,Sheet1!R13)>0 -> FALSE | J13: =COUNTIF('Duplicates_with_Master DB'!$A:$A,Sheet1!S13)>0 -> FALSE | K13: =COUNTIF('Duplicates_with_Master DB'!$A:$A,Sheet1!T13)>0 -> FALSE | L13: =M13 & IF(COUNTA(N13:T13), ", " & _xlfn.TEXTJOIN(", ", TRUE, N13:T13), "") -> 98161222 | M13: 98161222 | U13: operations@laderach.com.sg
A14: Shinagi | B14: Iwan | D14: =COUNTIF('Duplicates_with_Master DB'!$A:$A,Sheet1!M14)>0 -> FALSE | E14: =COUNTIF('Duplicates_with_Master DB'!$A:$A,Sheet1!N14)>0 -> FALSE | F14: =COUNTIF('Duplicates_with_Master DB'!$A:$A,Sheet1!O14)>0 -> FALSE | G14: =COUNTIF('Duplicates_with_Master DB'!$A:$A,Sheet1!P14)>0 -> FALSE | H14: =COUNTIF('Duplicates_with_Master DB'!$A:$A,Sheet1!Q14)>0 -> FALSE | I14: =COUNTIF('Duplicates_with_Master DB'!$A:$A,Sheet1!R14)>0 -> FALSE | J14: =COUNTIF('Duplicates_with_Master DB'!$A:$A,Sheet1!S14)>0 -> FALSE | K14: =COUNTIF('Duplicates_with_Master DB'!$A:$A,Sheet1!T14)>0 -> FALSE | L14: =M14 & IF(COUNTA(N14:T14), ", " & _xlfn.TEXTJOIN(", ", TRUE, N14:T14), "") -> 93403891 | M14: 93403891 | U14: iwan.golf@yahoo.com
A15: Toho Singapore | B15: Takizawa Ritsuko | D15: =COUNTIF('Duplicates_with_Master DB'!$A:$A,Sheet1!M15)>0 -> FALSE | E15: =COUNTIF('Duplicates_with_Master DB'!$A:$A,Sheet1!N15)>0 -> FALSE | F15: =COUNTIF('Duplicates_with_Master DB'!$A:$A,Sheet1!O15)>0 -> FALSE | G15: =COUNTIF('Duplicates_with_Master DB'!$A:$A,Sheet1!P15)>0 -> FALSE | H15: =COUNTIF('Duplicates_with_Master DB'!$A:$A,Sheet1!Q15)>0 -> FALSE | I15: =COUNTIF('Duplicates_with_Master DB'!$A:$A,Sheet1!R15)>0 -> FALSE | J15: =COUNTIF('Duplicates_with_Master DB'!$A:$A,Sheet1!S15)>0 -> FALSE | K15: =COUNTIF('Duplicates_with_Master DB'!$A:$A,Sheet1!T15)>0 -> FALSE | L15: =M15 & IF(COUNTA(N15:T15), ", " & _xlfn.TEXTJOIN(", ", TRUE, N15:T15), "") -> 90939387 | M15: 90939387 | U15: takizawa@to-ho.com.sg
A16: The Tasting Room by Ikon Mart | B16: Aung Than Htay | D16: =COUNTIF('Duplicates_with_Master DB'!$A:$A,Sheet1!M16)>0 -> FALSE | E16: =COUNTIF('Duplicates_with_Master DB'!$A:$A,Sheet1!N16)>0 -> FALSE | F16: =COUNTIF('Duplicates_with_Master DB'!$A:$A,Sheet1!O16)>0 -> FALSE | G16: =COUNTIF('Duplicates_with_Master DB'!$A:$A,Sheet1!P16)>0 -> FALSE | H16: =COUNTIF('Duplicates_with_Master DB'!$A:$A,Sheet1!Q16)>0 -> FALSE | I16: =COUNTIF('Duplicates_with_Master DB'!$A:$A,Sheet1!R16)>0 -> FALSE | J16: =COUNTIF('Duplicates_with_Master DB'!$A:$A,Sheet1!S16)>0 -> FALSE | K16: =COUNTIF('Duplicates_with_Master DB'!$A:$A,Sheet1!T16)>0 -> FALSE | L16: =M16 & IF(COUNTA(N16:T16), ", " & _xlfn.TEXTJOIN(", ", TRUE, N16:T16), "") | U16: ath@ikonmart.com
A17: Food joy | B17: Linus | D17: =COUNTIF('Duplicates_with_Master DB'!$A:$A,Sheet1!M17)>0 -> FALSE | E17: =COUNTIF('Duplicates_with_Master DB'!$A:$A,Sheet1!N17)>0 -> FALSE | F17: =COUNTIF('Duplicates_with_Master DB'!$A:$A,Sheet1!O17)>0 -> FALSE | G17: =COUNTIF('Duplicates_with_Master DB'!$A:$A,Sheet1!P17)>0 -> FALSE | H17: =COUNTIF('Duplicates_with_Master DB'!$A:$A,Sheet1!Q17)>0 -> FALSE | I17: =COUNTIF('Duplicates_with_Master DB'!$A:$A,Sheet1!R17)>0 -> FALSE | J17: =COUNTIF('Duplicates_with_Master DB'!$A:$A,Sheet1!S17)>0 -> FALSE | K17: =COUNTIF('Duplicates_with_Master DB'!$A:$A,Sheet1!T17)>0 -> FALSE | L17: =M17 & IF(COUNTA(N17:T17), ", " & _xlfn.TEXTJOIN(", ", TRUE, N17:T17), "") -> 84995150 | M17: 84995150 | U17: linus.low@bluecube.com.sg
A18: Tiong Hoe Specialty Coffee | B18: Juliana | D18: =COUNTIF('Duplicates_with_Master DB'!$A:$A,Sheet1!M18)>0 -> FALSE | E18: =COUNTIF('Duplicates_with_Master DB'!$A:$A,Sheet1!N18)>0 -> FALSE | F18: =COUNTIF('Duplicates_with_Master DB'!$A:$A,Sheet1!O18)>0 -> FALSE | G18: =COUNTIF('Duplicates_with_Master DB'!$A:$A,Sheet1!P18)>0 -> FALSE | H18: =COUNTIF('Duplicates_with_Master DB'!$A:$A,Sheet1!Q18)>0 -> FALSE | I18: =COUNTIF('Duplicates_with_Master DB'!$A:$A,Sheet1!R18)>0 -> FALSE | J18: =COUNTIF('Duplicates_with_Master DB'!$A:$A,Sheet1!S18)>0 -> FALSE | K18: =COUNTIF('Duplicates_with_Master DB'!$A:$A,Sheet1!T18)>0 -> FALSE | L18: =M18 & IF(COUNTA(N18:T18), ", " & _xlfn.TEXTJOIN(", ", TRUE, N18:T18), "") -> 91299697 | M18: 91299697 | U18: accounts@tionghoe.com
A19: Niveken Pte ltd | B19: Kevin | D19: =COUNTIF('Duplicates_with_Master DB'!$A:$A,Sheet1!M19)>0 -> FALSE | E19: =COUNTIF('Duplicates_with_Master DB'!$A:$A,Sheet1!N19)>0 -> FALSE | F19: =COUNTIF('Duplicates_with_Master DB'!$A:$A,Sheet1!O19)>0 -> FALSE | G19: =COUNTIF('Duplicates_with_Master DB'!$A:$A,Sheet1!P19)>0 -> FALSE | H19: =COUNTIF('Duplicates_with_Master DB'!$A:$A,Sheet1!Q19)>0 -> FALSE | I19: =COUNTIF('Duplicates_with_Master DB'!$A:$A,Sheet1!R19)>0 -> FALSE | J19: =COUNTIF('Duplicates_with_Master DB'!$A:$A,Sheet1!S19)>0 -> FALSE | K19: =COUNTIF('Duplicates_with_Master DB'!$A:$A,Sheet1!T19)>0 -> FALSE | L19: =M19 & IF(COUNTA(N19:T19), ", " & _xlfn.TEXTJOIN(", ", TRUE, N19:T19), "") -> 96891318 | M19: 96891318 | U19: kevin@niveken.com
A20: Restaurant Brands International | B20: Yu Shan | D20: =COUNTIF('Duplicates_with_Master DB'!$A:$A,Sheet1!M20)>0 -> FALSE | E20: =COUNTIF('Duplicates_with_Master DB'!$A:$A,Sheet1!N20)>0 -> FALSE | F20: =COUNTIF('Duplicates_with_Master DB'!$A:$A,Sheet1!O20)>0 -> FALSE | G20: =COUNTIF('Duplicates_with_Master DB'!$A:$A,Sheet1!P20)>0 -> FALSE | H20: =COUNTIF('Duplicates_with_Master DB'!$A:$A,Sheet1!Q20)>0 -> FALSE | I20: =COUNTIF('Duplicates_with_Master DB'!$A:$A,Sheet1!R20)>0 -> FALSE | J20: =COUNTIF('Duplicates_with_Master DB'!$A:$A,Sheet1!S20)>0 -> FALSE | K20: =COUNTIF('Duplicates_with_Master DB'!$A:$A,Sheet1!T20)>0 -> FALSE | L20: =M20 & IF(COUNTA(N20:T20), ", " & _xlfn.TEXTJOIN(", ", TRUE, N20:T20), "") -> 83485931 | M20: 83485931 | U20: yushan9513@gmail.com
A21: Best food | B21: Donald Yap | D21: =COUNTIF('Duplicates_with_Master DB'!$A:$A,Sheet1!M21)>0 -> FALSE | E21: =COUNTIF('Duplicates_with_Master DB'!$A:$A,Sheet1!N21)>0 -> FALSE | F21: =COUNTIF('Duplicates_with_Master DB'!$A:$A,Sheet1!O21)>0 -> FALSE | G21: =COUNTIF('Duplicates_with_Master DB'!$A:$A,Sheet1!P21)>0 -> FALSE | H21: =COUNTIF('Duplicates_with_Master DB'!$A:$A,Sheet1!Q21)>0 -> FALSE | I21: =COUNTIF('Duplicates_with_Master DB'!$A:$A,Sheet1!R21)>0 -> FALSE | J21: =COUNTIF('Duplicates_with_Master DB'!$A:$A,Sheet1!S21)>0 -> FALSE | K21: =COUNTIF('Duplicates_with_Master DB'!$A:$A,Sheet1!T21)>0 -> FALSE | L21: =M21 & IF(COUNTA(N21:T21), ", " & _xlfn.TEXTJOIN(", ", TRUE, N21:T21), "") | U21: donald@hzgreenpulp.com
A22: mok corner | B22: Jacky | D22: =COUNTIF('Duplicates_with_Master DB'!$A:$A,Sheet1!M22)>0 -> FALSE | E22: =COUNTIF('Duplicates_with_Master DB'!$A:$A,Sheet1!N22)>0 -> FALSE | F22: =COUNTIF('Duplicates_with_Master DB'!$A:$A,Sheet1!O22)>0 -> FALSE | G22: =COUNTIF('Duplicates_with_Master DB'!$A:$A,Sheet1!P22)>0 -> FALSE | H22: =COUNTIF('Duplicates_with_Master DB'!$A:$A,Sheet1!Q22)>0 -> FALSE | I22: =COUNTIF('Duplicates_with_Master DB'!$A:$A,Sheet1!R22)>0 -> FALSE | J22: =COUNTIF('Duplicates_with_Master DB'!$A:$A,Sheet1!S22)>0 -> FALSE | K22: =COUNTIF('Duplicates_with_Master DB'!$A:$A,Sheet1!T22)>0 -> FALSE | L22: =M22 & IF(COUNTA(N22:T22), ", " & _xlfn.TEXTJOIN(", ", TRUE, N22:T22), "") | U22: jackychin@mokcorner.com
A23: Wok hey | B23: Kaidi | D23: =COUNTIF('Duplicates_with_Master DB'!$A:$A,Sheet1!M23)>0 -> FALSE | E23: =COUNTIF('Duplicates_with_Master DB'!$A:$A,Sheet1!N23)>0 -> FALSE | F23: =COUNTIF('Duplicates_with_Master DB'!$A:$A,Sheet1!O23)>0 -> FALSE | G23: =COUNTIF('Duplicates_with_Master DB'!$A:$A,Sheet1!P23)>0 -> FALSE | H23: =COUNTIF('Duplicates_with_Master DB'!$A:$A,Sheet1!Q23)>0 -> FALSE | I23: =COUNTIF('Duplicates_with_Master DB'!$A:$A,Sheet1!R23)>0 -> FALSE | J23: =COUNTIF('Duplicates_with_Master DB'!$A:$A,Sheet1!S23)>0 -> FALSE | K23: =COUNTIF('Duplicates_with_Master DB'!$A:$A,Sheet1!T23)>0 -> FALSE | L23: =M23 & IF(COUNTA(N23:T23), ", " & _xlfn.TEXTJOIN(", ", TRUE, N23:T23), "") -> 81869437 | M23: 81869437 | U23: kaidi@wokhey.sg
A24: Mintplus | B24: Shen | D24: =COUNTIF('Duplicates_with_Master DB'!$A:$A,Sheet1!M24)>0 -> FALSE | E24: =COUNTIF('Duplicates_with_Master DB'!$A:$A,Sheet1!N24)>0 -> FALSE | F24: =COUNTIF('Duplicates_with_Master DB'!$A:$A,Sheet1!O24)>0 -> FALSE | G24: =COUNTIF('Duplicates_with_Master DB'!$A:$A,Sheet1!P24)>0 -> FALSE | H24: =COUNTIF('Duplicates_with_Master DB'!$A:$A,Sheet1!Q24)>0 -> FALSE | I24: =COUNTIF('Duplicates_with_Master DB'!$A:$A,Sheet1!R24)>0 -> FALSE | J24: =COUNTIF('Duplicates_with_Master DB'!$A:$A,Sheet1!S24)>0 -> FALSE | K24: =COUNTIF('Duplicates_with_Master DB'!$A:$A,Sheet1!T24)>0 -> FALSE | L24: =M24 & IF(COUNTA(N24:T24), ", " & _xlfn.TEXTJOIN(", ", TRUE, N24:T24), "") -> 90359556 | M24: 90359556 | U24: shine10607@126.com
A25: eG Innovations | B25: Adan Yap | D25: =COUNTIF('Duplicates_with_Master DB'!$A:$A,Sheet1!M25)>0 -> FALSE | E25: =COUNTIF('Duplicates_with_Master DB'!$A:$A,Sheet1!N25)>0 -> FALSE | F25: =COUNTIF('Duplicates_with_Master DB'!$A:$A,Sheet1!O25)>0 -> FALSE | G25: =COUNTIF('Duplicates_with_Master DB'!$A:$A,Sheet1!P25)>0 -> FALSE | H25: =COUNTIF('Duplicates_with_Master DB'!$A:$A,Sheet1!Q25)>0 -> FALSE | I25: =COUNTIF('Duplicates_with_Master DB'!$A:$A,Sheet1!R25)>0 -> FALSE | J25: =COUNTIF('Duplicates_with_Master DB'!$A:$A,Sheet1!S25)>0 -> FALSE | K25: =COUNTIF('Duplicates_with_Master DB'!$A:$A,Sheet1!T25)>0 -> FALSE | L25: =M25 & IF(COUNTA(N25:T25), ", " & _xlfn.TEXTJOIN(", ", TRUE, N25:T25), "") -> 97389832 | M25: 97389832 | U25: adan.yap@eginnovations.com
A26: Westlake | B26: Matthew Lim | D26: =COUNTIF('Duplicates_with_Master DB'!$A:$A,Sheet1!M26)>0 -> FALSE | E26: =COUNTIF('Duplicates_with_Master DB'!$A:$A,Sheet1!N26)>0 -> FALSE | F26: =COUNTIF('Duplicates_with_Master DB'!$A:$A,Sheet1!O26)>0 -> FALSE | G26: =COUNTIF('Duplicates_with_Master DB'!$A:$A,Sheet1!P26)>0 -> FALSE | H26: =COUNTIF('Duplicates_with_Master DB'!$A:$A,Sheet1!Q26)>0 -> FALSE | I26: =COUNTIF('Duplicates_with_Master DB'!$A:$A,Sheet1!R26)>0 -> FALSE | J26: =COUNTIF('Duplicates_with_Master DB'!$A:$A,Sheet1!S26)>0 -> FALSE | K26: =COUNTIF('Duplicates_with_Master DB'!$A:$A,Sheet1!T26)>0 -> FALSE | L26: =M26 & IF(COUNTA(N26:T26), ", " & _xlfn.TEXTJOIN(", ", TRUE, N26:T26), "") -> 97495989 | M26: 97495989 | U26: matthew.lim@westlake.com.sg
A27: LAGNAA barefoot dining | B27: RAJAKUMARI | D27: =COUNTIF('Duplicates_with_Master DB'!$A:$A,Sheet1!M27)>0 -> FALSE | E27: =COUNTIF('Duplicates_with_Master DB'!$A:$A,Sheet1!N27)>0 -> FALSE | F27: =COUNTIF('Duplicates_with_Master DB'!$A:$A,Sheet1!O27)>0 -> FALSE | G27: =COUNTIF('Duplicates_with_Master DB'!$A:$A,Sheet1!P27)>0 -> FALSE | H27: =COUNTIF('Duplicates_with_Master DB'!$A:$A,Sheet1!Q27)>0 -> FALSE | I27: =COUNTIF('Duplicates_with_Master DB'!$A:$A,Sheet1!R27)>0 -> FALSE | J27: =COUNTIF('Duplicates_with_Master DB'!$A:$A,Sheet1!S27)>0 -> FALSE | K27: =COUNTIF('Duplicates_with_Master DB'!$A:$A,Sheet1!T27)>0 -> FALSE | L27: =M27 & IF(COUNTA(N27:T27), ", " & _xlfn.TEXTJOIN(", ", TRUE, N27:T27), "") -> 92399702 | M27: 92399702 | U27: barefootdining@lagnaa.com
A28: Mr kneady | B28: Lionel | D28: =COUNTIF('Duplicates_with_Master DB'!$A:$A,Sheet1!M28)>0 -> FALSE | E28: =COUNTIF('Duplicates_with_Master DB'!$A:$A,Sheet1!N28)>0 -> FALSE | F28: =COUNTIF('Duplicates_with_Master DB'!$A:$A,Sheet1!O28)>0 -> FALSE | G28: =COUNTIF('Duplicates_with_Master DB'!$A:$A,Sheet1!P28)>0 -> FALSE | H28: =COUNTIF('Duplicates_with_Master DB'!$A:$A,Sheet1!Q28)>0 -> FALSE | I28: =COUNTIF('Duplicates_with_Master DB'!$A:$A,Sheet1!R28)>0 -> FALSE | J28: =COUNTIF('Duplicates_with_Master DB'!$A:$A,Sheet1!S28)>0 -> FALSE | K28: =COUNTIF('Duplicates_with_Master DB'!$A:$A,Sheet1!T28)>0 -> FALSE | L28: =M28 & IF(COUNTA(N28:T28), ", " & _xlfn.TEXTJOIN(", ", TRUE, N28:T28), "") -> 91718507 | M28: 91718507 | U28: mrkneadys@gmail.com
A29: Chuanwei | B29: Soon | D29: =COUNTIF('Duplicates_with_Master DB'!$A:$A,Sheet1!M29)>0 -> FALSE | E29: =COUNTIF('Duplicates_with_Master DB'!$A:$A,Sheet1!N29)>0 -> FALSE | F29: =COUNTIF('Duplicates_with_Master DB'!$A:$A,Sheet1!O29)>0 -> FALSE | G29: =COUNTIF('Duplicates_with_Master DB'!$A:$A,Sheet1!P29)>0 -> FALSE | H29: =COUNTIF('Duplicates_with_Master DB'!$A:$A,Sheet1!Q29)>0 -> FALSE | I29: =COUNTIF('Duplicates_with_Master DB'!$A:$A,Sheet1!R29)>0 -> FALSE | J29: =COUNTIF('Duplicates_with_Master DB'!$A:$A,Sheet1!S29)>0 -> FALSE | K29: =COUNTIF('Duplicates_with_Master DB'!$A:$A,Sheet1!T29)>0 -> FALSE | L29: =M29 & IF(COUNTA(N29:T29), ", " & _xlfn.TEXTJOIN(", ", TRUE, N29:T29), "") -> 87231077 | M29: 87231077 | U29: torres6994331@hotmail.com
A30: Mikigold Intl | B30: Michael Goh | D30: =COUNTIF('Duplicates_with_Master DB'!$A:$A,Sheet1!M30)>0 -> FALSE | E30: =COUNTIF('Duplicates_with_Master DB'!$A:$A,Sheet1!N30)>0 -> FALSE | F30: =COUNTIF('Duplicates_with_Master DB'!$A:$A,Sheet1!O30)>0 -> FALSE | G30: =COUNTIF('Duplicates_with_Master DB'!$A:$A,Sheet1!P30)>0 -> FALSE | H30: =COUNTIF('Duplicates_with_Master DB'!$A:$A,Sheet1!Q30)>0 -> FALSE | I30: =COUNTIF('Duplicates_with_Master DB'!$A:$A,Sheet1!R30)>0 -> FALSE | J30: =COUNTIF('Duplicates_with_Master DB'!$A:$A,Sheet1!S30)>0 -> FALSE | K30: =COUNTIF('Duplicates_with_Master DB'!$A:$A,Sheet1!T30)>0 -> FALSE | L30: =M30 & IF(COUNTA(N30:T30), ", " & _xlfn.TEXTJOIN(", ", TRUE, N30:T30), "") -> 96452781 | M30: 96452781 | U30: mikigold8@yahoo.com
A31: Bbq master | B31: Wang Shuang | D31: =COUNTIF('Duplicates_with_Master DB'!$A:$A,Sheet1!M31)>0 -> FALSE | E31: =COUNTIF('Duplicates_with_Master DB'!$A:$A,Sheet1!N31)>0 -> FALSE | F31: =COUNTIF('Duplicates_with_Master DB'!$A:$A,Sheet1!O31)>0 -> FALSE | G31: =COUNTIF('Duplicates_with_Master DB'!$A:$A,Sheet1!P31)>0 -> FALSE | H31: =COUNTIF('Duplicates_with_Master DB'!$A:$A,Sheet1!Q31)>0 -> FALSE | I31: =COUNTIF('Duplicates_with_Master DB'!$A:$A,Sheet1!R31)>0 -> FALSE | J31: =COUNTIF('Duplicates_with_Master DB'!$A:$A,Sheet1!S31)>0 -> FALSE | K31: =COUNTIF('Duplicates_with_Master DB'!$A:$A,Sheet1!T31)>0 -> FALSE | L31: =M31 & IF(COUNTA(N31:T31), ", " & _xlfn.TEXTJOIN(", ", TRUE, N31:T31), "") -> 83835380 | M31: 83835380 | U31: aiwinnie@hotmail.com
A32: Innergia Labs | B32: Jack Lim | D32: =COUNTIF('Duplicates_with_Master DB'!$A:$A,Sheet1!M32)>0 -> FALSE | E32: =COUNTIF('Duplicates_with_Master DB'!$A:$A,Sheet1!N32)>0 -> FALSE | F32: =COUNTIF('Duplicates_with_Master DB'!$A:$A,Sheet1!O32)>0 -> FALSE | G32: =COUNTIF('Duplicates_with_Master DB'!$A:$A,Sheet1!P32)>0 -> FALSE | H32: =COUNTIF('Duplicates_with_Master DB'!$A:$A,Sheet1!Q32)>0 -> FALSE | I32: =COUNTIF('Duplicates_with_Master DB'!$A:$A,Sheet1!R32)>0 -> FALSE | J32: =COUNTIF('Duplicates_with_Master DB'!$A:$A,Sheet1!S32)>0 -> FALSE | K32: =COUNTIF('Duplicates_with_Master DB'!$A:$A,Sheet1!T32)>0 -> FALSE | L32: =M32 & IF(COUNTA(N32:T32), ", " & _xlfn.TEXTJOIN(", ", TRUE, N32:T32), "") -> 93834249 | M32: 93834249 | U32: jack@sycarda.ai
A33: Unimas Consulting Solutions Pte Ltd | B33: Muru | D33: =COUNTIF('Duplicates_with_Master DB'!$A:$A,Sheet1!M33)>0 -> FALSE | E33: =COUNTIF('Duplicates_with_Master DB'!$A:$A,Sheet1!N33)>0 -> FALSE | F33: =COUNTIF('Duplicates_with_Master DB'!$A:$A,Sheet1!O33)>0 -> FALSE | G33: =COUNTIF('Duplicates_with_Master DB'!$A:$A,Sheet1!P33)>0 -> FALSE | H33: =COUNTIF('Duplicates_with_Master DB'!$A:$A,Sheet1!Q33)>0 -> FALSE | I33: =COUNTIF('Duplicates_with_Master DB'!$A:$A,Sheet1!R33)>0 -> FALSE | J33: =COUNTIF('Duplicates_with_Master DB'!$A:$A,Sheet1!S33)>0 -> FALSE | K33: =COUNTIF('Duplicates_with_Master DB'!$A:$A,Sheet1!T33)>0 -> FALSE | L33: =M33 & IF(COUNTA(N33:T33), ", " & _xlfn.TEXTJOIN(", ", TRUE, N33:T33), "") | U33: cm.anand@outlook.com
A34: INNovate QrLock Pte Ltd | B34: Miko | D34: =COUNTIF('Duplicates_with_Master DB'!$A:$A,Sheet1!M34)>0 -> FALSE | E34: =COUNTIF('Duplicates_with_Master DB'!$A:$A,Sheet1!N34)>0 -> FALSE | F34: =COUNTIF('Duplicates_with_Master DB'!$A:$A,Sheet1!O34)>0 -> FALSE | G34: =COUNTIF('Duplicates_with_Master DB'!$A:$A,Sheet1!P34)>0 -> FALSE | H34: =COUNTIF('Duplicates_with_Master DB'!$A:$A,Sheet1!Q34)>0 -> FALSE | I34: =COUNTIF('Duplicates_with_Master DB'!$A:$A,Sheet1!R34)>0 -> FALSE | J34: =COUNTIF('Duplicates_with_Master DB'!$A:$A,Sheet1!S34)>0 -> FALSE | K34: =COUNTIF('Duplicates_with_Master DB'!$A:$A,Sheet1!T34)>0 -> FALSE | L34: =M34 & IF(COUNTA(N34:T34), ", " & _xlfn.TEXTJOIN(", ", TRUE, N34:T34), "") -> 98383655 | M34: 98383655 | U34: sales2qrlock@outlook.com
A35: far east | B35: Elisa chew | D35: =COUNTIF('Duplicates_with_Master DB'!$A:$A,Sheet1!M35)>0 -> FALSE | E35: =COUNTIF('Duplicates_with_Master DB'!$A:$A,Sheet1!N35)>0 -> FALSE | F35: =COUNTIF('Duplicates_with_Master DB'!$A:$A,Sheet1!O35)>0 -> FALSE | G35: =COUNTIF('Duplicates_with_Master DB'!$A:$A,Sheet1!P35)>0 -> FALSE | H35: =COUNTIF('Duplicates_with_Master DB'!$A:$A,Sheet1!Q35)>0 -> FALSE | I35: =COUNTIF('Duplicates_with_Master DB'!$A:$A,Sheet1!R35)>0 -> FALSE | J35: =COUNTIF('Duplicates_with_Master DB'!$A:$A,Sheet1!S35)>0 -> FALSE | K35: =COUNTIF('Duplicates_with_Master DB'!$A:$A,Sheet1!T35)>0 -> FALSE | L35: =M35 & IF(COUNTA(N35:T35), ", " & _xlfn.TEXTJOIN(", ", TRUE, N35:T35), "") -> 91138102 | M35: 91138102 | U35: elisachew@fareast.com.sg
A36: maslina | B36: ms nazilah nasir | D36: =COUNTIF('Duplicates_with_Master DB'!$A:$A,Sheet1!M36)>0 -> FALSE | E36: =COUNTIF('Duplicates_with_Master DB'!$A:$A,Sheet1!N36)>0 -> FALSE | F36: =COUNTIF('Duplicates_with_Master DB'!$A:$A,Sheet1!O36)>0 -> FALSE | G36: =COUNTIF('Duplicates_with_Master DB'!$A:$A,Sheet1!P36)>0 -> FALSE | H36: =COUNTIF('Duplicates_with_Master DB'!$A:$A,Sheet1!Q36)>0 -> FALSE | I36: =COUNTIF('Duplicates_with_Master DB'!$A:$A,Sheet1!R36)>0 -> FALSE | J36: =COUNTIF('Duplicates_with_Master DB'!$A:$A,Sheet1!S36)>0 -> FALSE | K36: =COUNTIF('Duplicates_with_Master DB'!$A:$A,Sheet1!T36)>0 -> FALSE | L36: =M36 & IF(COUNTA(N36:T36), ", " & _xlfn.TEXTJOIN(", ", TRUE, N36:T36), "") -> 97515612 | M36: 97515612 | U36: marketing@delimaslina.com
A37: Vino sg | B37: Amith Anand | D37: =COUNTIF('Duplicates_with_Master DB'!$A:$A,Sheet1!M37)>0 -> FALSE | E37: =COUNTIF('Duplicates_with_Master DB'!$A:$A,Sheet1!N37)>0 -> FALSE | F37: =COUNTIF('Duplicates_with_Master DB'!$A:$A,Sheet1!O37)>0 -> FALSE | G37: =COUNTIF('Duplicates_with_Master DB'!$A:$A,Sheet1!P37)>0 -> FALSE | H37: =COUNTIF('Duplicates_with_Master DB'!$A:$A,Sheet1!Q37)>0 -> FALSE | I37: =COUNTIF('Duplicates_with_Master DB'!$A:$A,Sheet1!R37)>0 -> FALSE | J37: =COUNTIF('Duplicates_with_Master DB'!$A:$A,Sheet1!S37)>0 -> FALSE | K37: =COUNTIF('Duplicates_with_Master DB'!$A:$A,Sheet1!T37)>0 -> FALSE | L37: =M37 & IF(COUNTA(N37:T37), ", " & _xlfn.TEXTJOIN(", ", TRUE, N37:T37), "") -> 83390169 | M37: 83390169 | U37: contact@vino.sg
A38: Real inbound consulting | B38: Hayley Heah | D38: =COUNTIF('Duplicates_with_Master DB'!$A:$A,Sheet1!M38)>0 -> FALSE | E38: =COUNTIF('Duplicates_with_Master DB'!$A:$A,Sheet1!N38)>0 -> FALSE | F38: =COUNTIF('Duplicates_with_Master DB'!$A:$A,Sheet1!O38)>0 -> FALSE | G38: =COUNTIF('Duplicates_with_Master DB'!$A:$A,Sheet1!P38)>0 -> FALSE | H38: =COUNTIF('Duplicates_with_Master DB'!$A:$A,Sheet1!Q38)>0 -> FALSE | I38: =COUNTIF('Duplicates_with_Master DB'!$A:$A,Sheet1!R38)>0 -> FALSE | J38: =COUNTIF('Duplicates_with_Master DB'!$A:$A,Sheet1!S38)>0 -> FALSE | K38: =COUNTIF('Duplicates_with_Master DB'!$A:$A,Sheet1!T38)>0 -> FALSE | L38: =M38 & IF(COUNTA(N38:T38), ", " & _xlfn.TEXTJOIN(", ", TRUE, N38:T38), "") -> 83099505 | M38: 83099505 | U38: hayley@realinboundconsulting.com
A39: Marina Bay sands | B39: Eugene Chow | D39: =COUNTIF('Duplicates_with_Master DB'!$A:$A,Sheet1!M39)>0 -> FALSE | E39: =COUNTIF('Duplicates_with_Master DB'!$A:$A,Sheet1!N39)>0 -> FALSE | F39: =COUNTIF('Duplicates_with_Master DB'!$A:$A,Sheet1!O39)>0 -> FALSE | G39: =COUNTIF('Duplicates_with_Master DB'!$A:$A,Sheet1!P39)>0 -> FALSE | H39: =COUNTIF('Duplicates_with_Master DB'!$A:$A,Sheet1!Q39)>0 -> FALSE | I39: =COUNTIF('Duplicates_with_Master DB'!$A:$A,Sheet1!R39)>0 -> FALSE | J39: =COUNTIF('Duplicates_with_Master DB'!$A:$A,Sheet1!S39)>0 -> FALSE | K39: =COUNTIF('Duplicates_with_Master DB'!$A:$A,Sheet1!T39)>0 -> FALSE | L39: =M39 & IF(COUNTA(N39:T39), ", " & _xlfn.TEXTJOIN(", ", TRUE, N39:T39), "") -> 83280239 | M39: 83280239 | U39: eugene.chow@marinabaysands.com
A40: Cowpresso | B40: David | D40: =COUNTIF('Duplicates_with_Master DB'!$A:$A,Sheet1!M40)>0 -> FALSE | E40: =COUNTIF('Duplicates_with_Master DB'!$A:$A,Sheet1!N40)>0 -> FALSE | F40: =COUNTIF('Duplicates_with_Master DB'!$A:$A,Sheet1!O40)>0 -> FALSE | G40: =COUNTIF('Duplicates_with_Master DB'!$A:$A,Sheet1!P40)>0 -> FALSE | H40: =COUNTIF('Duplicates_with_Master DB'!$A:$A,Sheet1!Q40)>0 -> FALSE | I40: =COUNTIF('Duplicates_with_Master DB'!$A:$A,Sheet1!R40)>0 -> FALSE | J40: =COUNTIF('Duplicates_with_Master DB'!$A:$A,Sheet1!S40)>0 -> FALSE | K40: =COUNTIF('Duplicates_with_Master DB'!$A:$A,Sheet1!T40)>0 -> FALSE | L40: =M40 & IF(COUNTA(N40:T40), ", " & _xlfn.TEXTJOIN(", ", TRUE, N40:T40), "") -> 94300464 | M40: 94300464 | U40: david@cowpressocoffee.sg
...

Sheet Duplicates_with_Master DB
A1: number | B1: count_in_file1 | C1: count_in_file2
A2: 61006800 | B2: 1 | C2: 1
A3: 61234567 | B3: 2 | C3: 2
A4: 62046003 | B4: 1 | C4: 1
A5: 62134398 | B5: 2 | C5: 3
A6: 62134486 | B6: 1 | C6: 1
A7: 62134571 | B7: 1 | C7: 1
A8: 62212262 | B8: 2 | C8: 1
A9: 62212522 | B9: 1 | C9: 1
A10: 62213114 | B10: 1 | C10: 1
A11: 62213988 | B11: 1 | C11: 1
A12: 62214282 | B12: 1 | C12: 1
A13: 62216678 | B13: 1 | C13: 1
A14: 62217056 | B14: 1 | C14: 2
... A303: 98873377 | B303: 9 | C303: 1
